Workbook

Sheet 1. Start here
B2: Sweet Equity Valuation Model — read this sheet first
B4: WHAT THIS WORKBOOK DOES
B5: It values management's 'sweet equity' (the B ordinary shares) in a private equity deal. The key idea:
B6: those shares only get paid at exit AFTER a queue of other instruments is repaid with rolled-up
B7: interest. That makes them behave like a lottery ticket on a good exit — technically, a call option —
B8: and we price that ticket two ways: with the Black-Scholes formula (sheet 4) and with a 10,000-scenario
B9: Monte Carlo simulation (sheet 5). Plain-words explanations are in the Word guide
B10: ('Sweet Equity Valuation Guide.docx'); its numbers match this file sheet by sheet.
B12: THE HYPOTHETICAL DEAL (used consistently everywhere in this file)
B13: At completion, €240m of total equity funding went in, in 5 classes, repaid at exit in this order:
B14: 1. Shareholder loan notes (sponsor) €180m, 10% interest that rolls up ('PIK') — paid first
B15: 2. Preference shares (sponsor) €30m, 8% rolling dividend — paid second
... B46: exist to price exactly that chance.

Sheet 2. Inputs
B2: Inputs — change only the YELLOW cells
B3: Every row answers: what is this, and what happens to the SWEET EQUITY value if I increase it?
E5: WHAT IS THIS? (in plain words) | F5: IF I INCREASE IT, THE SWEET EQUITY VALUE ...
B6: A. The pot and the option inputs
B7: Value of the whole pot today (V0) | C7: 240 | D7: €m | E7: Today's value of ALL 5 classes together (company value minus bank debt). At the deal date it equals what everyone paid in: €240m. | F7: RISES A LOT. The sweet equity is the leveraged slice at the back of the queue: +10% pot can be +30% sweet equity.
B8: Expected years until exit (T) | C8: 4 | D8: years | E8: How long until the company is sold and the payout queue actually runs. PE deals: typically 3–5 years. | F8: TWO-SIDED: more years for the pot to grow (good) but the queue rolls up 10%/8% interest every extra year (bad). See sheet 6.
B9: Risk-free interest rate (r) | C9: 0.03 | D9: p.a. | E9: Government bond yield for the same horizon & currency. The ONLY rate in an option model — no WACC anywhere (risk is carried by volatility). | F9: Rises slightly (technical effect, small).
B10: Volatility of the pot (sigma) | C10: 0.45 | D10: p.a. | E10: How widely the pot's value swings per year. Measured from listed comparable companies, adjusted for this deal's debt. 35–60% is normal for buyouts. | F10: RISES. More swing = more chance of clearing the queue; the downside is capped at zero anyway. THE key judgment input — check sheet 6.
B11: Cash leakage before exit (q) | C11: 0 | D11: p.a. | E11: Value paid OUT of the pot before exit (cash dividends/interest). 0 if all interest rolls up (fully 'PIK'), as here. | F11: FALLS. A smaller pot at exit hurts the back of the queue most.
B12: Marketability discount (DLOM) | C12: 0.15 | E12: End haircut because managers can't sell these shares before exit (locked in). Typical 10–30%. | F12: FALLS one-for-one (it's a direct haircut on the conclusion).
B13: B. The payout queue (from the funds flow statement + loan notes/articles)
B14: 1. Shareholder loans — amount | C14: 180 | D14: €m | E14: Sponsor's loan notes: repaid FIRST at exit, with rolled-up interest. | F14: FALLS — the queue ahead of management grows.
B15: 1. Shareholder loans — PIK rate | C15: 0.1 | D15: p.a. | E15: Interest that rolls up and compounds (no cash paid). €180m at 10% = €263.5m owed after 4 years. | F15: FALLS — and the damage grows with every extra year of holding.
B16: 2. Preference shares — amount | C16: 30 | D16: €m | E16: Sponsor's preference shares: repaid SECOND, with rolled-up dividend. | F16: FALLS (same mechanism as above).
B17: 2. Preference shares — dividend rate | C17: 0.08 | D17: p.a. | E17: Fixed cumulative dividend that rolls up. | F17: FALLS.
B18: 3. Rollover loan notes — amount | C18: 10 | D18: €m | E18: Management's own reinvested money, as loan notes: repaid THIRD, before any ordinary shares. | F18: FALLS for the B shares (still ahead of them in the queue) — though management holds this class too.
B19: 3. Rollover loan notes — PIK rate | C19: 0.1 | D19: p.a. | E19: Rolls up like the shareholder loans. | F19: FALLS (for the B shares).
B20: C. The ordinary shares (from the shareholders' agreement / MIP)
B21: Management share of ordinaries — base | C21: 0.15 | E21: The B shares' slice of everything left after the queue. The heart of the deal. | F21: RISES proportionally (15% → 16% is ~+7% value).
B22: Management share — after ratchet | C22: 0.2 | E22: The stepped-up slice if the ratchet triggers. Used in the Monte Carlo (a formula can't handle it). | F22: RISES, in the good scenarios only.
B23: Ratchet trigger: sponsor money-multiple ≥ | C23: 2.5 | E23: The ratchet fires when the sponsor gets back at least this multiple of its €227m. Read the exact test in the MIP! | F23: A LOWER trigger raises value (fires more often); a higher one lowers it.
B24: Sponsor total money in | C24: 227 | D24: €m | E24: Loans €180m + prefs €30m + A ordinaries €17m. The denominator of the money-multiple test. | F24: Higher cost = harder to hit the trigger = ratchet fires less often = value falls slightly.
B25: Management price paid for B shares | C25: 3 | D25: €m | E25: What management actually pays. NOT used in the valuation math — it's the benchmark to compare the answer against. | F25: No effect on value; only on the comparison.
B26: D. When does the exit happen? (Monte Carlo only)
B27: Probability the exit is in year 3 | C27: 0.3 | E27: Instead of one fixed exit year, the simulation draws the year per scenario. The three weights must sum to 100% (green check below). | F27: Earlier exits = smaller rolled-up queue but less growth time; the net effect shows on sheet 5.
B28: Probability the exit is in year 4 | C28: 0.4
B29: Probability the exit is in year 5 | C29: 0.3
B31: Check: the three exit-year probabilities sum to 100% | C31: =C27+C28+C29 -> 0

Sheet 3. Waterfall playground
B2: Waterfall playground — follow the money at any exit you like | H2: INPUTS USED ON THIS SHEET (linked from sheet 2 — change them THERE)
B3: This sheet contains NO option math. It just runs the payout queue once, for an exit value you type. | H3: Years until exit (T) | I3: ='2. Inputs'!$C$8 -> 0
B4: Play with the yellow cell until the mechanics feel obvious — then the two valuation sheets will make sense. | H4: 1. Loans — amount | I4: ='2. Inputs'!$C$14 -> 0 | O4: Exit value | P4: 1 Loans | Q4: 2 Prefs | R4: 3 Rollover | S4: 4 A ords | T4: 5 B SWEET
H5: 1. Loans — PIK rate | I5: ='2. Inputs'!$C$15 -> 0 | O5: 0 | P5: =MIN(O5,$C$12) -> 0 | Q5: =MIN(MAX(O5-$C$12,0),$C$13) -> 0 | R5: =MIN(MAX(O5-$C$12-$C$13,0),$C$14) -> 0 | S5: =(1-$I$10)*MAX(O5-$C$15,0) -> 0 | T5: =$I$10*MAX(O5-$C$15,0) -> 0
B6: Try an exit: the pot is sold after T years for ... (type any amount) | C6: 400 | D6: €m | F6: Try 200 (sweet equity gets nothing), 319 (the tipping point), 500 (jackpot). | H6: 2. Prefs — amount | I6: ='2. Inputs'!$C$16 -> 0 | O6: 25 | P6: =MIN(O6,$C$12) -> 0 | Q6: =MIN(MAX(O6-$C$12,0),$C$13) -> 0 | R6: =MIN(MAX(O6-$C$12-$C$13,0),$C$14) -> 0 | S6: =(1-$I$10)*MAX(O6-$C$15,0) -> 0 | T6: =$I$10*MAX(O6-$C$15,0) -> 0
H7: 2. Prefs — rate | I7: ='2. Inputs'!$C$17 -> 0 | O7: 50 | P7: =MIN(O7,$C$12) -> 0 | Q7: =MIN(MAX(O7-$C$12,0),$C$13) -> 0 | R7: =MIN(MAX(O7-$C$12-$C$13,0),$C$14) -> 0 | S7: =(1-$I$10)*MAX(O7-$C$15,0) -> 0 | T7: =$I$10*MAX(O7-$C$15,0) -> 0
H8: 3. Rollover — amount | I8: ='2. Inputs'!$C$18 -> 0 | O8: 75 | P8: =MIN(O8,$C$12) -> 0 | Q8: =MIN(MAX(O8-$C$12,0),$C$13) -> 0 | R8: =MIN(MAX(O8-$C$12-$C$13,0),$C$14) -> 0 | S8: =(1-$I$10)*MAX(O8-$C$15,0) -> 0 | T8: =$I$10*MAX(O8-$C$15,0) -> 0
B9: The payout queue at exit (interest rolled up over T years) | H9: 3. Rollover — rate | I9: ='2. Inputs'!$C$19 -> 0 | O9: 100 | P9: =MIN(O9,$C$12) -> 0 | Q9: =MIN(MAX(O9-$C$12,0),$C$13) -> 0 | R9: =MIN(MAX(O9-$C$12-$C$13,0),$C$14) -> 0 | S9: =(1-$I$10)*MAX(O9-$C$15,0) -> 0 | T9: =$I$10*MAX(O9-$C$15,0) -> 0
B10: Class (paid in this order) | C10: Owed at exit €m | D10: Actually paid €m | E10: Still left €m | F10: How the row works | H10: Management share of ordinaries | I10: ='2. Inputs'!$C$21 -> 0 | O10: 125 | P10: =MIN(O10,$C$12) -> 0 | Q10: =MIN(MAX(O10-$C$12,0),$C$13) -> 0 | R10: =MIN(MAX(O10-$C$12-$C$13,0),$C$14) -> 0 | S10: =(1-$I$10)*MAX(O10-$C$15,0) -> 0 | T10: =$I$10*MAX(O10-$C$15,0) -> 0
B11: Money available | E11: =$C$6 -> 0 | F11: The whole sale price of the pot. | H11: Management price paid | I11: ='2. Inputs'!$C$25 -> 0 | O11: 150 | P11: =MIN(O11,$C$12) -> 0 | Q11: =MIN(MAX(O11-$C$12,0),$C$13) -> 0 | R11: =MIN(MAX(O11-$C$12-$C$13,0),$C$14) -> 0 | S11: =(1-$I$10)*MAX(O11-$C$15,0) -> 0 | T11: =$I$10*MAX(O11-$C$15,0) -> 0
B12: 1. Shareholder loans (sponsor) | C12: =$I$4*(1+$I$5)^$I$3 -> 0 | D12: =MIN(E11,C12) -> 0 | E12: =E11-D12 -> 0 | F12: Owed = 180 × 1.10^T. The row takes the smaller of what's owed and what's left. | O12: 175 | P12: =MIN(O12,$C$12) -> 0 | Q12: =MIN(MAX(O12-$C$12,0),$C$13) -> 0 | R12: =MIN(MAX(O12-$C$12-$C$13,0),$C$14) -> 0 | S12: =(1-$I$10)*MAX(O12-$C$15,0) -> 0 | T12: =$I$10*MAX(O12-$C$15,0) -> 0
B13: 2. Preference shares (sponsor) | C13: =$I$6*(1+$I$7)^$I$3 -> 0 | D13: =MIN(E12,C13) -> 0 | E13: =E12-D13 -> 0 | F13: Only reached if row 1 was paid in full. | O13: 200 | P13: =MIN(O13,$C$12) -> 0 | Q13: =MIN(MAX(O13-$C$12,0),$C$13) -> 0 | R13: =MIN(MAX(O13-$C$12-$C$13,0),$C$14) -> 0 | S13: =(1-$I$10)*MAX(O13-$C$15,0) -> 0 | T13: =$I$10*MAX(O13-$C$15,0) -> 0
B14: 3. Rollover loan notes (management) | C14: =$I$8*(1+$I$9)^$I$3 -> 0 | D14: =MIN(E13,C14) -> 0 | E14: =E13-D14 -> 0 | F14: Management's safer layer: ahead of ALL ordinary shares. | O14: 225 | P14: =MIN(O14,$C$12) -> 0 | Q14: =MIN(MAX(O14-$C$12,0),$C$13) -> 0 | R14: =MIN(MAX(O14-$C$12-$C$13,0),$C$14) -> 0 | S14: =(1-$I$10)*MAX(O14-$C$15,0) -> 0 | T14: =$I$10*MAX(O14-$C$15,0) -> 0
B15: The hurdle: total owed ahead of the ordinaries | C15: =SUM(C12:C14) -> 0 | F15: Below this exit value, ordinary shares get NOTHING. This is the option's 'strike'. | O15: 250 | P15: =MIN(O15,$C$12) -> 0 | Q15: =MIN(MAX(O15-$C$12,0),$C$13) -> 0 | R15: =MIN(MAX(O15-$C$12-$C$13,0),$C$14) -> 0 | S15: =(1-$I$10)*MAX(O15-$C$15,0) -> 0 | T15: =$I$10*MAX(O15-$C$15,0) -> 0
B16: 4. A ordinary shares (sponsor) — rest × (1 − mgmt %) | D16: =(1-$I$10)*E14 -> 0 | F16: The residual is split by the ordinary-share percentages. | O16: 275 | P16: =MIN(O16,$C$12) -> 0 | Q16: =MIN(MAX(O16-$C$12,0),$C$13) -> 0 | R16: =MIN(MAX(O16-$C$12-$C$13,0),$C$14) -> 0 | S16: =(1-$I$10)*MAX(O16-$C$15,0) -> 0 | T16: =$I$10*MAX(O16-$C$15,0) -> 0
B17: 5. B ordinary shares — SWEET EQUITY — rest × mgmt % | D17: =$I$10*E14 -> 0 | F17: What this whole workbook is about. (The ratchet is ignored on this sheet for clarity.) | O17: 300 | P17: =MIN(O17,$C$12) -> 0 | Q17: =MIN(MAX(O17-$C$12,0),$C$13) -> 0 | R17: =MIN(MAX(O17-$C$12-$C$13,0),$C$14) -> 0 | S17: =(1-$I$10)*MAX(O17-$C$15,0) -> 0 | T17: =$I$10*MAX(O17-$C$15,0) -> 0
B18: Check: every euro accounted for | D18: =SUM(D12:D14)+D16+D17 -> 0 | F18: Must equal the yellow exit value above. | O18: 325 | P18: =MIN(O18,$C$12) -> 0 | Q18: =MIN(MAX(O18-$C$12,0),$C$13) -> 0 | R18: =MIN(MAX(O18-$C$12-$C$13,0),$C$14) -> 0 | S18: =(1-$I$10)*MAX(O18-$C$15,0) -> 0 | T18: =$I$10*MAX(O18-$C$15,0) -> 0
O19: 350 | P19: =MIN(O19,$C$12) -> 0 | Q19: =MIN(MAX(O19-$C$12,0),$C$13) -> 0 | R19: =MIN(MAX(O19-$C$12-$C$13,0),$C$14) -> 0 | S19: =(1-$I$10)*MAX(O19-$C$15,0) -> 0 | T19: =$I$10*MAX(O19-$C$15,0) -> 0
B20: Management's multiple on its money | C20: =IF($I$11>0,D17/$I$11,0) -> 0 | O20: 375 | P20: =MIN(O20,$C$12) -> 0 | Q20: =MIN(MAX(O20-$C$12,0),$C$13) -> 0 | R20: =MIN(MAX(O20-$C$12-$C$13,0),$C$14) -> 0 | S20: =(1-$I$10)*MAX(O20-$C$15,0) -> 0 | T20: =$I$10*MAX(O20-$C$15,0) -> 0
O21: 400 | P21: =MIN(O21,$C$12) -> 0 | Q21: =MIN(MAX(O21-$C$12,0),$C$13) -> 0 | R21: =MIN(MAX(O21-$C$12-$C$13,0),$C$14) -> 0 | S21: =(1-$I$10)*MAX(O21-$C$15,0) -> 0 | T21: =$I$10*MAX(O21-$C$15,0) -> 0
B22: The 'hockey stick' — each class's payout across all possible exits | O22: 425 | P22: =MIN(O22,$C$12) -> 0 | Q22: =MIN(MAX(O22-$C$12,0),$C$13) -> 0 | R22: =MIN(MAX(O22-$C$12-$C$13,0),$C$14) -> 0 | S22: =(1-$I$10)*MAX(O22-$C$15,0) -> 0 | T22: =$I$10*MAX(O22-$C$15,0) -> 0
B23: Drawn from the table in columns O–T (exit values €0–700m in €25m steps). | O23: 450 | P23: =MIN(O23,$C$12) -> 0 | Q23: =MIN(MAX(O23-$C$12,0),$C$13) -> 0 | R23: =MIN(MAX(O23-$C$12-$C$13,0),$C$14) -> 0 | S23: =(1-$I$10)*MAX(O23-$C$15,0) -> 0 | T23: =$I$10*MAX(O23-$C$15,0) -> 0
O24: 475 | P24: =MIN(O24,$C$12) -> 0 | Q24: =MIN(MAX(O24-$C$12,0),$C$13) -> 0 | R24: =MIN(MAX(O24-$C$12-$C$13,0),$C$14) -> 0 | S24: =(1-$I$10)*MAX(O24-$C$15,0) -> 0 | T24: =$I$10*MAX(O24-$C$15,0) -> 0
O25: 500 | P25: =MIN(O25,$C$12) -> 0 | Q25: =MIN(MAX(O25-$C$12,0),$C$13) -> 0 | R25: =MIN(MAX(O25-$C$12-$C$13,0),$C$14) -> 0 | S25: =(1-$I$10)*MAX(O25-$C$15,0) -> 0 | T25: =$I$10*MAX(O25-$C$15,0) -> 0
O26: 525 | P26: =MIN(O26,$C$12) -> 0 | Q26: =MIN(MAX(O26-$C$12,0),$C$13) -> 0 | R26: =MIN(MAX(O26-$C$12-$C$13,0),$C$14) -> 0 | S26: =(1-$I$10)*MAX(O26-$C$15,0) -> 0 | T26: =$I$10*MAX(O26-$C$15,0) -> 0
O27: 550 | P27: =MIN(O27,$C$12) -> 0 | Q27: =MIN(MAX(O27-$C$12,0),$C$13) -> 0 | R27: =MIN(MAX(O27-$C$12-$C$13,0),$C$14) -> 0 | S27: =(1-$I$10)*MAX(O27-$C$15,0) -> 0 | T27: =$I$10*MAX(O27-$C$15,0) -> 0
O28: 575 | P28: =MIN(O28,$C$12) -> 0 | Q28: =MIN(MAX(O28-$C$12,0),$C$13) -> 0 | R28: =MIN(MAX(O28-$C$12-$C$13,0),$C$14) -> 0 | S28: =(1-$I$10)*MAX(O28-$C$15,0) -> 0 | T28: =$I$10*MAX(O28-$C$15,0) -> 0
O29: 600 | P29: =MIN(O29,$C$12) -> 0 | Q29: =MIN(MAX(O29-$C$12,0),$C$13) -> 0 | R29: =MIN(MAX(O29-$C$12-$C$13,0),$C$14) -> 0 | S29: =(1-$I$10)*MAX(O29-$C$15,0) -> 0 | T29: =$I$10*MAX(O29-$C$15,0) -> 0
O30: 625 | P30: =MIN(O30,$C$12) -> 0 | Q30: =MIN(MAX(O30-$C$12,0),$C$13) -> 0 | R30: =MIN(MAX(O30-$C$12-$C$13,0),$C$14) -> 0 | S30: =(1-$I$10)*MAX(O30-$C$15,0) -> 0 | T30: =$I$10*MAX(O30-$C$15,0) -> 0
O31: 650 | P31: =MIN(O31,$C$12) -> 0 | Q31: =MIN(MAX(O31-$C$12,0),$C$13) -> 0 | R31: =MIN(MAX(O31-$C$12-$C$13,0),$C$14) -> 0 | S31: =(1-$I$10)*MAX(O31-$C$15,0) -> 0 | T31: =$I$10*MAX(O31-$C$15,0) -> 0
O32: 675 | P32: =MIN(O32,$C$12) -> 0 | Q32: =MIN(MAX(O32-$C$12,0),$C$13) -> 0 | R32: =MIN(MAX(O32-$C$12-$C$13,0),$C$14) -> 0 | S32: =(1-$I$10)*MAX(O32-$C$15,0) -> 0 | T32: =$I$10*MAX(O32-$C$15,0) -> 0
O33: 700 | P33: =MIN(O33,$C$12) -> 0 | Q33: =MIN(MAX(O33-$C$12,0),$C$13) -> 0 | R33: =MIN(MAX(O33-$C$12-$C$13,0),$C$14) -> 0 | S33: =(1-$I$10)*MAX(O33-$C$15,0) -> 0 | T33: =$I$10*MAX(O33-$C$15,0) -> 0

Sheet 4. OPM valuation
B2: Valuation 1 — Black-Scholes formula (the 'Option Pricing Method') | H2: INPUTS USED ON THIS SHEET (linked from sheet 2 — change them THERE)
B3: Prices each class as 'the value between two points of the queue'. Plain-words logic: Word guide §6. | H3: V0 — the pot today | I3: ='2. Inputs'!$C$7 -> 0
H4: T — years until exit | I4: ='2. Inputs'!$C$8 -> 0
B5: STEP 1 — Roll the queue up to exit (same numbers as sheet 3) | F5: Common review error: forgetting the roll-up and using day-one amounts. | H5: r — risk-free rate | I5: ='2. Inputs'!$C$9 -> 0
B6: Owed to 1. Shareholder loans at exit | C6: =$I$9*(1+$I$10)^$I$4 -> 0 | H6: sigma — volatility | I6: ='2. Inputs'!$C$10 -> 0
B7: Owed to 2. Preference shares at exit | C7: =$I$11*(1+$I$12)^$I$4 -> 0 | H7: q — cash leakage | I7: ='2. Inputs'!$C$11 -> 0
B8: Owed to 3. Rollover notes at exit | C8: =$I$13*(1+$I$14)^$I$4 -> 0 | H8: DLOM | I8: ='2. Inputs'!$C$12 -> 0
B9: Queue point B1 (loans done) | C9: =C6 -> 0 | H9: 1. Loans — amount | I9: ='2. Inputs'!$C$14 -> 0
B10: Queue point B2 (loans + prefs done) | C10: =C6+C7 -> 0 | H10: 1. Loans — PIK rate | I10: ='2. Inputs'!$C$15 -> 0
B11: Queue point B3 = THE HURDLE (whole queue done) | C11: =C6+C7+C8 -> 0 | H11: 2. Prefs — amount | I11: ='2. Inputs'!$C$16 -> 0
H12: 2. Prefs — rate | I12: ='2. Inputs'!$C$17 -> 0
B13: STEP 2 — Price 'all value above a threshold' with Black-Scholes | H13: 3. Rollover — amount | I13: ='2. Inputs'!$C$18 -> 0
B14: C(B) = today's worth of receiving everything above B at exit. Larger B ⇒ smaller value. | H14: 3. Rollover — rate | I14: ='2. Inputs'!$C$19 -> 0
B15: Threshold B (€m, at exit) | C15: d1 (helper) | D15: d2 (helper) | E15: C(B) €m today | F15: Meaning | H15: Management share of ordinaries | I15: ='2. Inputs'!$C$21 -> 0
B16: 0 | C16: n/a | D16: n/a | E16: =$I$3*EXP(-$I$7*$I$4) -> 0 | F16: Everything above zero = the whole pot. | H16: Management price paid | I16: ='2. Inputs'!$C$25 -> 0
B17: =$C$9 -> 0 | C17: =(LN($I$3/$C$9)+($I$5-$I$7+0.5*$I$6^2)*$I$4)/($I$6*SQRT($I$4)) -> 0 | D17: =C17-$I$6*SQRT($I$4) -> 0 | E17: =$I$3*EXP(-$I$7*$I$4)*NORMSDIST(C17)-$C$9*EXP(-$I$5*$I$4)*NORMSDIST(D17) -> 0 | F17: All value after the loans are repaid.
B18: =$C$10 -> 0 | C18: =(LN($I$3/$C$10)+($I$5-$I$7+0.5*$I$6^2)*$I$4)/($I$6*SQRT($I$4)) -> 0 | D18: =C18-$I$6*SQRT($I$4) -> 0 | E18: =$I$3*EXP(-$I$7*$I$4)*NORMSDIST(C18)-$C$10*EXP(-$I$5*$I$4)*NORMSDIST(D18) -> 0 | F18: All value after loans + prefs.
B19: =$C$11 -> 0 | C19: =(LN($I$3/$C$11)+($I$5-$I$7+0.5*$I$6^2)*$I$4)/($I$6*SQRT($I$4)) -> 0 | D19: =C19-$I$6*SQRT($I$4) -> 0 | E19: =$I$3*EXP(-$I$7*$I$4)*NORMSDIST(C19)-$C$11*EXP(-$I$5*$I$4)*NORMSDIST(D19) -> 0 | F19: All value above the full hurdle = the ordinary shares' pool.
B21: STEP 3 — Each class = the value between its two thresholds
B22: Class | C22: In words | E22: Value €m
B23: 1. Shareholder loans | C23: whole pot minus 'above B1' | E23: =E16-E17 -> 0
B24: 2. Preference shares | C24: 'above B1' minus 'above B2' | E24: =E17-E18 -> 0
B25: 3. Rollover loan notes | C25: 'above B2' minus 'above B3' | E25: =E18-E19 -> 0
B26: 4. A ordinaries | C26: (1 − mgmt %) × 'above the hurdle' | E26: =(1-$I$15)*E19 -> 0
B27: 5. B SWEET EQUITY | C27: mgmt % × 'above the hurdle' | E27: =$I$15*E19 -> 0
B28: SELF-CHECK: the five classes must add up to the whole pot | E28: =SUM(E23:E27) -> 0 | F28: =IF(ABS(E28-$I$3*EXP(-$I$7*$I$4))<0.01,"OK — adds up to V0","BROKEN — investigate!") -> 0
B30: STEP 4 — Conclusion
B31: Sweet equity before marketability discount | C31: =E27 -> 0
B32: Marketability discount (DLOM, sheet 2) | C32: =$I$8 -> 0
B33: SWEET EQUITY VALUE (Black-Scholes) | C33: =E27*(1-$I$8) -> 0
B34: … vs what management pays | C34: =$I$16 -> 0
B35: … vs 'naive' value ignoring the option (pot − hurdle, floored at 0, × mgmt %) | C35: =MAX($I$3-C11,0)*$I$15 -> 0
B37: The gap between the naive €0 and the model's answer is the priced-in CHANCE of a good exit.
B38: Limits of the formula: one fixed exit date, no ratchet. For those → sheet 5.

Sheet 5. Monte Carlo
A1: Valuation 2 — Monte Carlo: 10,000 simulated futures through the FULL 5-class waterfall
A2: Each row below is one possible future: a random exit year and exit value, pushed through the same queue as sheet 3, | V2: RESULTS (per class, averaged over all futures, in today's money)
A3: including the ratchet (which a formula cannot price). Press F9 to draw new futures — the summary barely moves. | V3: 1. Shareholder loans | W3: =AVERAGE(O10:O10009) -> 0
V4: 2. Preference shares | W4: =AVERAGE(P10:P10009) -> 0
V5: 3. Rollover loan notes | W5: =AVERAGE(Q10:Q10009) -> 0
V6: 4. A ordinary shares | W6: =AVERAGE(R10:R10009) -> 0
V7: 5. B SWEET EQUITY — before DLOM | W7: =AVERAGE(S10:S10009) -> 0
A8: one row = one simulated future | B8: random 0–1: picks the exit year | C8: exit year for this future (3/4/5) | D8: random 'luck factor' (bell curve) | E8: V0 grown to year T with luck Z | F8: loans rolled up to year T | G8: prefs rolled up | H8: rollover notes rolled up | I8: queue position 1 fills first | J8: then position 2 | K8: then position 3 | L8: the residual above the queue | M8: 1 if sponsor multiple ≥ trigger | N8: mgmt % (base or ratcheted) × residual | O8: paid 1, in today's money | S8: the number we average | T8: whole pot, today's money | V8: SWEET EQUITY VALUE (after DLOM) | W8: =AVERAGE(S10:S10009)*(1-$W$29) -> 0
A9: Future # | B9: u | C9: T | D9: Z | E9: Pot at exit | F9: Owed 1 | G9: Owed 2 | H9: Owed 3 | I9: Paid 1 | J9: Paid 2 | K9: Paid 3 | L9: Left for ords | M9: Ratchet? | N9: B sweet payout | O9: PV 1 | P9: PV 2 | Q9: PV 3 | R9: PV A ords | S9: PV B sweet | T9: PV total
A10: 1 | B10: =RAND() -> 0 | C10: =IF(B10<$W$41,3,IF(B10<$W$41+$W$42,4,5)) -> 0 | D10: =NORMSINV(RAND()) -> 0 | E10: =$W$25*EXP(($W$26-$W$28-0.5*$W$27^2)*C10+$W$27*SQRT(C10)*D10) -> 0 | F10: =$W$30*(1+$W$31)^C10 -> 0 | G10: =$W$32*(1+$W$33)^C10 -> 0 | H10: =$W$34*(1+$W$35)^C10 -> 0 | I10: =MIN(E10,F10) -> 0 | J10: =MIN(E10-I10,G10) -> 0 | K10: =MIN(E10-I10-J10,H10) -> 0 | L10: =E10-I10-J10-K10 -> 0 | M10: =IF((I10+J10+(1-$W$36)*L10)/$W$39>=$W$38,1,0) -> 0 | N10: =IF(M10=1,$W$37,$W$36)*L10 -> 0 | O10: =EXP(-$W$26*C10)*I10 -> 0 | P10: =EXP(-$W$26*C10)*J10 -> 0 | Q10: =EXP(-$W$26*C10)*K10 -> 0 | R10: =EXP(-$W$26*C10)*(L10-N10) -> 0 | S10: =EXP(-$W$26*C10)*N10 -> 0 | T10: =EXP(-$W$26*C10)*E10 -> 0 | V10: TRUST CHECKS
A11: 2 | B11: =RAND() -> 0 | C11: =IF(B11<$W$41,3,IF(B11<$W$41+$W$42,4,5)) -> 0 | D11: =NORMSINV(RAND()) -> 0 | E11: =$W$25*EXP(($W$26-$W$28-0.5*$W$27^2)*C11+$W$27*SQRT(C11)*D11) -> 0 | F11: =$W$30*(1+$W$31)^C11 -> 0 | G11: =$W$32*(1+$W$33)^C11 -> 0 | H11: =$W$34*(1+$W$35)^C11 -> 0 | I11: =MIN(E11,F11) -> 0 | J11: =MIN(E11-I11,G11) -> 0 | K11: =MIN(E11-I11-J11,H11) -> 0 | L11: =E11-I11-J11-K11 -> 0 | M11: =IF((I11+J11+(1-$W$36)*L11)/$W$39>=$W$38,1,0) -> 0 | N11: =IF(M11=1,$W$37,$W$36)*L11 -> 0 | O11: =EXP(-$W$26*C11)*I11 -> 0 | P11: =EXP(-$W$26*C11)*J11 -> 0 | Q11: =EXP(-$W$26*C11)*K11 -> 0 | R11: =EXP(-$W$26*C11)*(L11-N11) -> 0 | S11: =EXP(-$W$26*C11)*N11 -> 0 | T11: =EXP(-$W$26*C11)*E11 -> 0 | V11: Random error of the sweet equity number (±) | W11: =STDEV(S10:S10009)/SQRT(10000) -> 0
A12: 3 | B12: =RAND() -> 0 | C12: =IF(B12<$W$41,3,IF(B12<$W$41+$W$42,4,5)) -> 0 | D12: =NORMSINV(RAND()) -> 0 | E12: =$W$25*EXP(($W$26-$W$28-0.5*$W$27^2)*C12+$W$27*SQRT(C12)*D12) -> 0 | F12: =$W$30*(1+$W$31)^C12 -> 0 | G12: =$W$32*(1+$W$33)^C12 -> 0 | H12: =$W$34*(1+$W$35)^C12 -> 0 | I12: =MIN(E12,F12) -> 0 | J12: =MIN(E12-I12,G12) -> 0 | K12: =MIN(E12-I12-J12,H12) -> 0 | L12: =E12-I12-J12-K12 -> 0 | M12: =IF((I12+J12+(1-$W$36)*L12)/$W$39>=$W$38,1,0) -> 0 | N12: =IF(M12=1,$W$37,$W$36)*L12 -> 0 | O12: =EXP(-$W$26*C12)*I12 -> 0 | P12: =EXP(-$W$26*C12)*J12 -> 0 | Q12: =EXP(-$W$26*C12)*K12 -> 0 | R12: =EXP(-$W$26*C12)*(L12-N12) -> 0 | S12: =EXP(-$W$26*C12)*N12 -> 0 | T12: =EXP(-$W$26*C12)*E12 -> 0 | V12: All classes together (must be ≈ the pot, V0) | W12: =AVERAGE(T10:T10009) -> 0
A13: 4 | B13: =RAND() -> 0 | C13: =IF(B13<$W$41,3,IF(B13<$W$41+$W$42,4,5)) -> 0 | D13: =NORMSINV(RAND()) -> 0 | E13: =$W$25*EXP(($W$26-$W$28-0.5*$W$27^2)*C13+$W$27*SQRT(C13)*D13) -> 0 | F13: =$W$30*(1+$W$31)^C13 -> 0 | G13: =$W$32*(1+$W$33)^C13 -> 0 | H13: =$W$34*(1+$W$35)^C13 -> 0 | I13: =MIN(E13,F13) -> 0 | J13: =MIN(E13-I13,G13) -> 0 | K13: =MIN(E13-I13-J13,H13) -> 0 | L13: =E13-I13-J13-K13 -> 0 | M13: =IF((I13+J13+(1-$W$36)*L13)/$W$39>=$W$38,1,0) -> 0 | N13: =IF(M13=1,$W$37,$W$36)*L13 -> 0 | O13: =EXP(-$W$26*C13)*I13 -> 0 | P13: =EXP(-$W$26*C13)*J13 -> 0 | Q13: =EXP(-$W$26*C13)*K13 -> 0 | R13: =EXP(-$W$26*C13)*(L13-N13) -> 0 | S13: =EXP(-$W$26*C13)*N13 -> 0 | T13: =EXP(-$W$26*C13)*E13 -> 0 | V13: Black-Scholes said (sheet 4, before DLOM) | W13: ='4. OPM valuation'!E27 -> 0
A14: 5 | B14: =RAND() -> 0 | C14: =IF(B14<$W$41,3,IF(B14<$W$41+$W$42,4,5)) -> 0 | D14: =NORMSINV(RAND()) -> 0 | E14: =$W$25*EXP(($W$26-$W$28-0.5*$W$27^2)*C14+$W$27*SQRT(C14)*D14) -> 0 | F14: =$W$30*(1+$W$31)^C14 -> 0 | G14: =$W$32*(1+$W$33)^C14 -> 0 | H14: =$W$34*(1+$W$35)^C14 -> 0 | I14: =MIN(E14,F14) -> 0 | J14: =MIN(E14-I14,G14) -> 0 | K14: =MIN(E14-I14-J14,H14) -> 0 | L14: =E14-I14-J14-K14 -> 0 | M14: =IF((I14+J14+(1-$W$36)*L14)/$W$39>=$W$38,1,0) -> 0 | N14: =IF(M14=1,$W$37,$W$36)*L14 -> 0 | O14: =EXP(-$W$26*C14)*I14 -> 0 | P14: =EXP(-$W$26*C14)*J14 -> 0 | Q14: =EXP(-$W$26*C14)*K14 -> 0 | R14: =EXP(-$W$26*C14)*(L14-N14) -> 0 | S14: =EXP(-$W$26*C14)*N14 -> 0 | T14: =EXP(-$W$26*C14)*E14 -> 0
A15: 6 | B15: =RAND() -> 0 | C15: =IF(B15<$W$41,3,IF(B15<$W$41+$W$42,4,5)) -> 0 | D15: =NORMSINV(RAND()) -> 0 | E15: =$W$25*EXP(($W$26-$W$28-0.5*$W$27^2)*C15+$W$27*SQRT(C15)*D15) -> 0 | F15: =$W$30*(1+$W$31)^C15 -> 0 | G15: =$W$32*(1+$W$33)^C15 -> 0 | H15: =$W$34*(1+$W$35)^C15 -> 0 | I15: =MIN(E15,F15) -> 0 | J15: =MIN(E15-I15,G15) -> 0 | K15: =MIN(E15-I15-J15,H15) -> 0 | L15: =E15-I15-J15-K15 -> 0 | M15: =IF((I15+J15+(1-$W$36)*L15)/$W$39>=$W$38,1,0) -> 0 | N15: =IF(M15=1,$W$37,$W$36)*L15 -> 0 | O15: =EXP(-$W$26*C15)*I15 -> 0 | P15: =EXP(-$W$26*C15)*J15 -> 0 | Q15: =EXP(-$W$26*C15)*K15 -> 0 | R15: =EXP(-$W$26*C15)*(L15-N15) -> 0 | S15: =EXP(-$W$26*C15)*N15 -> 0 | T15: =EXP(-$W$26*C15)*E15 -> 0 | V15: WHAT THE 10,000 FUTURES LOOK LIKE
A16: 7 | B16: =RAND() -> 0 | C16: =IF(B16<$W$41,3,IF(B16<$W$41+$W$42,4,5)) -> 0 | D16: =NORMSINV(RAND()) -> 0 | E16: =$W$25*EXP(($W$26-$W$28-0.5*$W$27^2)*C16+$W$27*SQRT(C16)*D16) -> 0 | F16: =$W$30*(1+$W$31)^C16 -> 0 | G16: =$W$32*(1+$W$33)^C16 -> 0 | H16: =$W$34*(1+$W$35)^C16 -> 0 | I16: =MIN(E16,F16) -> 0 | J16: =MIN(E16-I16,G16) -> 0 | K16: =MIN(E16-I16-J16,H16) -> 0 | L16: =E16-I16-J16-K16 -> 0 | M16: =IF((I16+J16+(1-$W$36)*L16)/$W$39>=$W$38,1,0) -> 0 | N16: =IF(M16=1,$W$37,$W$36)*L16 -> 0 | O16: =EXP(-$W$26*C16)*I16 -> 0 | P16: =EXP(-$W$26*C16)*J16 -> 0 | Q16: =EXP(-$W$26*C16)*K16 -> 0 | R16: =EXP(-$W$26*C16)*(L16-N16) -> 0 | S16: =EXP(-$W$26*C16)*N16 -> 0 | T16: =EXP(-$W$26*C16)*E16 -> 0 | V16: Chance the sweet equity ends up worth NOTHING | W16: =COUNTIF(N10:N10009,"<=0")/10000 -> 0
A17: 8 | B17: =RAND() -> 0 | C17: =IF(B17<$W$41,3,IF(B17<$W$41+$W$42,4,5)) -> 0 | D17: =NORMSINV(RAND()) -> 0 | E17: =$W$25*EXP(($W$26-$W$28-0.5*$W$27^2)*C17+$W$27*SQRT(C17)*D17) -> 0 | F17: =$W$30*(1+$W$31)^C17 -> 0 | G17: =$W$32*(1+$W$33)^C17 -> 0 | H17: =$W$34*(1+$W$35)^C17 -> 0 | I17: =MIN(E17,F17) -> 0 | J17: =MIN(E17-I17,G17) -> 0 | K17: =MIN(E17-I17-J17,H17) -> 0 | L17: =E17-I17-J17-K17 -> 0 | M17: =IF((I17+J17+(1-$W$36)*L17)/$W$39>=$W$38,1,0) -> 0 | N17: =IF(M17=1,$W$37,$W$36)*L17 -> 0 | O17: =EXP(-$W$26*C17)*I17 -> 0 | P17: =EXP(-$W$26*C17)*J17 -> 0 | Q17: =EXP(-$W$26*C17)*K17 -> 0 | R17: =EXP(-$W$26*C17)*(L17-N17) -> 0 | S17: =EXP(-$W$26*C17)*N17 -> 0 | T17: =EXP(-$W$26*C17)*E17 -> 0 | V17: Chance management at least gets its money back | W17: =COUNTIF(N10:N10009,">="&$W$40)/10000 -> 0
A18: 9 | B18: =RAND() -> 0 | C18: =IF(B18<$W$41,3,IF(B18<$W$41+$W$42,4,5)) -> 0 | D18: =NORMSINV(RAND()) -> 0 | E18: =$W$25*EXP(($W$26-$W$28-0.5*$W$27^2)*C18+$W$27*SQRT(C18)*D18) -> 0 | F18: =$W$30*(1+$W$31)^C18 -> 0 | G18: =$W$32*(1+$W$33)^C18 -> 0 | H18: =$W$34*(1+$W$35)^C18 -> 0 | I18: =MIN(E18,F18) -> 0 | J18: =MIN(E18-I18,G18) -> 0 | K18: =MIN(E18-I18-J18,H18) -> 0 | L18: =E18-I18-J18-K18 -> 0 | M18: =IF((I18+J18+(1-$W$36)*L18)/$W$39>=$W$38,1,0) -> 0 | N18: =IF(M18=1,$W$37,$W$36)*L18 -> 0 | O18: =EXP(-$W$26*C18)*I18 -> 0 | P18: =EXP(-$W$26*C18)*J18 -> 0 | Q18: =EXP(-$W$26*C18)*K18 -> 0 | R18: =EXP(-$W$26*C18)*(L18-N18) -> 0 | S18: =EXP(-$W$26*C18)*N18 -> 0 | T18: =EXP(-$W$26*C18)*E18 -> 0 | V18: How often the ratchet fires | W18: =AVERAGE(M10:M10009) -> 0
A19: 10 | B19: =RAND() -> 0 | C19: =IF(B19<$W$41,3,IF(B19<$W$41+$W$42,4,5)) -> 0 | D19: =NORMSINV(RAND()) -> 0 | E19: =$W$25*EXP(($W$26-$W$28-0.5*$W$27^2)*C19+$W$27*SQRT(C19)*D19) -> 0 | F19: =$W$30*(1+$W$31)^C19 -> 0 | G19: =$W$32*(1+$W$33)^C19 -> 0 | H19: =$W$34*(1+$W$35)^C19 -> 0 | I19: =MIN(E19,F19) -> 0 | J19: =MIN(E19-I19,G19) -> 0 | K19: =MIN(E19-I19-J19,H19) -> 0 | L19: =E19-I19-J19-K19 -> 0 | M19: =IF((I19+J19+(1-$W$36)*L19)/$W$39>=$W$38,1,0) -> 0 | N19: =IF(M19=1,$W$37,$W$36)*L19 -> 0 | O19: =EXP(-$W$26*C19)*I19 -> 0 | P19: =EXP(-$W$26*C19)*J19 -> 0 | Q19: =EXP(-$W$26*C19)*K19 -> 0 | R19: =EXP(-$W$26*C19)*(L19-N19) -> 0 | S19: =EXP(-$W$26*C19)*N19 -> 0 | T19: =EXP(-$W$26*C19)*E19 -> 0 | V19: Median payout to sweet equity (at exit) | W19: =MEDIAN(N10:N10009) -> 0
A20: 11 | B20: =RAND() -> 0 | C20: =IF(B20<$W$41,3,IF(B20<$W$41+$W$42,4,5)) -> 0 | D20: =NORMSINV(RAND()) -> 0 | E20: =$W$25*EXP(($W$26-$W$28-0.5*$W$27^2)*C20+$W$27*SQRT(C20)*D20) -> 0 | F20: =$W$30*(1+$W$31)^C20 -> 0 | G20: =$W$32*(1+$W$33)^C20 -> 0 | H20: =$W$34*(1+$W$35)^C20 -> 0 | I20: =MIN(E20,F20) -> 0 | J20: =MIN(E20-I20,G20) -> 0 | K20: =MIN(E20-I20-J20,H20) -> 0 | L20: =E20-I20-J20-K20 -> 0 | M20: =IF((I20+J20+(1-$W$36)*L20)/$W$39>=$W$38,1,0) -> 0 | N20: =IF(M20=1,$W$37,$W$36)*L20 -> 0 | O20: =EXP(-$W$26*C20)*I20 -> 0 | P20: =EXP(-$W$26*C20)*J20 -> 0 | Q20: =EXP(-$W$26*C20)*K20 -> 0 | R20: =EXP(-$W$26*C20)*(L20-N20) -> 0 | S20: =EXP(-$W$26*C20)*N20 -> 0 | T20: =EXP(-$W$26*C20)*E20 -> 0 | V20: A lucky 1-in-100 payout (99th percentile) | W20: =PERCENTILE(N10:N10009,0.99) -> 0
A21: 12 | B21: =RAND() -> 0 | C21: =IF(B21<$W$41,3,IF(B21<$W$41+$W$42,4,5)) -> 0 | D21: =NORMSINV(RAND()) -> 0 | E21: =$W$25*EXP(($W$26-$W$28-0.5*$W$27^2)*C21+$W$27*SQRT(C21)*D21) -> 0 | F21: =$W$30*(1+$W$31)^C21 -> 0 | G21: =$W$32*(1+$W$33)^C21 -> 0 | H21: =$W$34*(1+$W$35)^C21 -> 0 | I21: =MIN(E21,F21) -> 0 | J21: =MIN(E21-I21,G21) -> 0 | K21: =MIN(E21-I21-J21,H21) -> 0 | L21: =E21-I21-J21-K21 -> 0 | M21: =IF((I21+J21+(1-$W$36)*L21)/$W$39>=$W$38,1,0) -> 0 | N21: =IF(M21=1,$W$37,$W$36)*L21 -> 0 | O21: =EXP(-$W$26*C21)*I21 -> 0 | P21: =EXP(-$W$26*C21)*J21 -> 0 | Q21: =EXP(-$W$26*C21)*K21 -> 0 | R21: =EXP(-$W$26*C21)*(L21-N21) -> 0 | S21: =EXP(-$W$26*C21)*N21 -> 0 | T21: =EXP(-$W$26*C21)*E21 -> 0 | V21: Note the paradox that confuses first-timers: a ~70% chance of zero AND a solid value.
A22: 13 | B22: =RAND() -> 0 | C22: =IF(B22<$W$41,3,IF(B22<$W$41+$W$42,4,5)) -> 0 | D22: =NORMSINV(RAND()) -> 0 | E22: =$W$25*EXP(($W$26-$W$28-0.5*$W$27^2)*C22+$W$27*SQRT(C22)*D22) -> 0 | F22: =$W$30*(1+$W$31)^C22 -> 0 | G22: =$W$32*(1+$W$33)^C22 -> 0 | H22: =$W$34*(1+$W$35)^C22 -> 0 | I22: =MIN(E22,F22) -> 0 | J22: =MIN(E22-I22,G22) -> 0 | K22: =MIN(E22-I22-J22,H22) -> 0 | L22: =E22-I22-J22-K22 -> 0 | M22: =IF((I22+J22+(1-$W$36)*L22)/$W$39>=$W$38,1,0) -> 0 | N22: =IF(M22=1,$W$37,$W$36)*L22 -> 0 | O22: =EXP(-$W$26*C22)*I22 -> 0 | P22: =EXP(-$W$26*C22)*J22 -> 0 | Q22: =EXP(-$W$26*C22)*K22 -> 0 | R22: =EXP(-$W$26*C22)*(L22-N22) -> 0 | S22: =EXP(-$W$26*C22)*N22 -> 0 | T22: =EXP(-$W$26*C22)*E22 -> 0 | V22: Both are true — the value lives in the rare, huge payoffs. That's an option.
A23: 14 | B23: =RAND() -> 0 | C23: =IF(B23<$W$41,3,IF(B23<$W$41+$W$42,4,5)) -> 0 | D23: =NORMSINV(RAND()) -> 0 | E23: =$W$25*EXP(($W$26-$W$28-0.5*$W$27^2)*C23+$W$27*SQRT(C23)*D23) -> 0 | F23: =$W$30*(1+$W$31)^C23 -> 0 | G23: =$W$32*(1+$W$33)^C23 -> 0 | H23: =$W$34*(1+$W$35)^C23 -> 0 | I23: =MIN(E23,F23) -> 0 | J23: =MIN(E23-I23,G23) -> 0 | K23: =MIN(E23-I23-J23,H23) -> 0 | L23: =E23-I23-J23-K23 -> 0 | M23: =IF((I23+J23+(1-$W$36)*L23)/$W$39>=$W$38,1,0) -> 0 | N23: =IF(M23=1,$W$37,$W$36)*L23 -> 0 | O23: =EXP(-$W$26*C23)*I23 -> 0 | P23: =EXP(-$W$26*C23)*J23 -> 0 | Q23: =EXP(-$W$26*C23)*K23 -> 0 | R23: =EXP(-$W$26*C23)*(L23-N23) -> 0 | S23: =EXP(-$W$26*C23)*N23 -> 0 | T23: =EXP(-$W$26*C23)*E23 -> 0
A24: 15 | B24: =RAND() -> 0 | C24: =IF(B24<$W$41,3,IF(B24<$W$41+$W$42,4,5)) -> 0 | D24: =NORMSINV(RAND()) -> 0 | E24: =$W$25*EXP(($W$26-$W$28-0.5*$W$27^2)*C24+$W$27*SQRT(C24)*D24) -> 0 | F24: =$W$30*(1+$W$31)^C24 -> 0 | G24: =$W$32*(1+$W$33)^C24 -> 0 | H24: =$W$34*(1+$W$35)^C24 -> 0 | I24: =MIN(E24,F24) -> 0 | J24: =MIN(E24-I24,G24) -> 0 | K24: =MIN(E24-I24-J24,H24) -> 0 | L24: =E24-I24-J24-K24 -> 0 | M24: =IF((I24+J24+(1-$W$36)*L24)/$W$39>=$W$38,1,0) -> 0 | N24: =IF(M24=1,$W$37,$W$36)*L24 -> 0 | O24: =EXP(-$W$26*C24)*I24 -> 0 | P24: =EXP(-$W$26*C24)*J24 -> 0 | Q24: =EXP(-$W$26*C24)*K24 -> 0 | R24: =EXP(-$W$26*C24)*(L24-N24) -> 0 | S24: =EXP(-$W$26*C24)*N24 -> 0 | T24: =EXP(-$W$26*C24)*E24 -> 0 | V24: INPUTS USED ON THIS SHEET (linked from sheet 2 — change them THERE)
A25: 16 | B25: =RAND() -> 0 | C25: =IF(B25<$W$41,3,IF(B25<$W$41+$W$42,4,5)) -> 0 | D25: =NORMSINV(RAND()) -> 0 | E25: =$W$25*EXP(($W$26-$W$28-0.5*$W$27^2)*C25+$W$27*SQRT(C25)*D25) -> 0 | F25: =$W$30*(1+$W$31)^C25 -> 0 | G25: =$W$32*(1+$W$33)^C25 -> 0 | H25: =$W$34*(1+$W$35)^C25 -> 0 | I25: =MIN(E25,F25) -> 0 | J25: =MIN(E25-I25,G25) -> 0 | K25: =MIN(E25-I25-J25,H25) -> 0 | L25: =E25-I25-J25-K25 -> 0 | M25: =IF((I25+J25+(1-$W$36)*L25)/$W$39>=$W$38,1,0) -> 0 | N25: =IF(M25=1,$W$37,$W$36)*L25 -> 0 | O25: =EXP(-$W$26*C25)*I25 -> 0 | P25: =EXP(-$W$26*C25)*J25 -> 0 | Q25: =EXP(-$W$26*C25)*K25 -> 0 | R25: =EXP(-$W$26*C25)*(L25-N25) -> 0 | S25: =EXP(-$W$26*C25)*N25 -> 0 | T25: =EXP(-$W$26*C25)*E25 -> 0 | V25: V0 — the pot today | W25: ='2. Inputs'!$C$7 -> 0
A26: 17 | B26: =RAND() -> 0 | C26: =IF(B26<$W$41,3,IF(B26<$W$41+$W$42,4,5)) -> 0 | D26: =NORMSINV(RAND()) -> 0 | E26: =$W$25*EXP(($W$26-$W$28-0.5*$W$27^2)*C26+$W$27*SQRT(C26)*D26) -> 0 | F26: =$W$30*(1+$W$31)^C26 -> 0 | G26: =$W$32*(1+$W$33)^C26 -> 0 | H26: =$W$34*(1+$W$35)^C26 -> 0 | I26: =MIN(E26,F26) -> 0 | J26: =MIN(E26-I26,G26) -> 0 | K26: =MIN(E26-I26-J26,H26) -> 0 | L26: =E26-I26-J26-K26 -> 0 | M26: =IF((I26+J26+(1-$W$36)*L26)/$W$39>=$W$38,1,0) -> 0 | N26: =IF(M26=1,$W$37,$W$36)*L26 -> 0 | O26: =EXP(-$W$26*C26)*I26 -> 0 | P26: =EXP(-$W$26*C26)*J26 -> 0 | Q26: =EXP(-$W$26*C26)*K26 -> 0 | R26: =EXP(-$W$26*C26)*(L26-N26) -> 0 | S26: =EXP(-$W$26*C26)*N26 -> 0 | T26: =EXP(-$W$26*C26)*E26 -> 0 | V26: r — risk-free rate | W26: ='2. Inputs'!$C$9 -> 0
A27: 18 | B27: =RAND() -> 0 | C27: =IF(B27<$W$41,3,IF(B27<$W$41+$W$42,4,5)) -> 0 | D27: =NORMSINV(RAND()) -> 0 | E27: =$W$25*EXP(($W$26-$W$28-0.5*$W$27^2)*C27+$W$27*SQRT(C27)*D27) -> 0 | F27: =$W$30*(1+$W$31)^C27 -> 0 | G27: =$W$32*(1+$W$33)^C27 -> 0 | H27: =$W$34*(1+$W$35)^C27 -> 0 | I27: =MIN(E27,F27) -> 0 | J27: =MIN(E27-I27,G27) -> 0 | K27: =MIN(E27-I27-J27,H27) -> 0 | L27: =E27-I27-J27-K27 -> 0 | M27: =IF((I27+J27+(1-$W$36)*L27)/$W$39>=$W$38,1,0) -> 0 | N27: =IF(M27=1,$W$37,$W$36)*L27 -> 0 | O27: =EXP(-$W$26*C27)*I27 -> 0 | P27: =EXP(-$W$26*C27)*J27 -> 0 | Q27: =EXP(-$W$26*C27)*K27 -> 0 | R27: =EXP(-$W$26*C27)*(L27-N27) -> 0 | S27: =EXP(-$W$26*C27)*N27 -> 0 | T27: =EXP(-$W$26*C27)*E27 -> 0 | V27: sigma — volatility | W27: ='2. Inputs'!$C$10 -> 0
A28: 19 | B28: =RAND() -> 0 | C28: =IF(B28<$W$41,3,IF(B28<$W$41+$W$42,4,5)) -> 0 | D28: =NORMSINV(RAND()) -> 0 | E28: =$W$25*EXP(($W$26-$W$28-0.5*$W$27^2)*C28+$W$27*SQRT(C28)*D28) -> 0 | F28: =$W$30*(1+$W$31)^C28 -> 0 | G28: =$W$32*(1+$W$33)^C28 -> 0 | H28: =$W$34*(1+$W$35)^C28 -> 0 | I28: =MIN(E28,F28) -> 0 | J28: =MIN(E28-I28,G28) -> 0 | K28: =MIN(E28-I28-J28,H28) -> 0 | L28: =E28-I28-J28-K28 -> 0 | M28: =IF((I28+J28+(1-$W$36)*L28)/$W$39>=$W$38,1,0) -> 0 | N28: =IF(M28=1,$W$37,$W$36)*L28 -> 0 | O28: =EXP(-$W$26*C28)*I28 -> 0 | P28: =EXP(-$W$26*C28)*J28 -> 0 | Q28: =EXP(-$W$26*C28)*K28 -> 0 | R28: =EXP(-$W$26*C28)*(L28-N28) -> 0 | S28: =EXP(-$W$26*C28)*N28 -> 0 | T28: =EXP(-$W$26*C28)*E28 -> 0 | V28: q — cash leakage | W28: ='2. Inputs'!$C$11 -> 0
A29: 20 | B29: =RAND() -> 0 | C29: =IF(B29<$W$41,3,IF(B29<$W$41+$W$42,4,5)) -> 0 | D29: =NORMSINV(RAND()) -> 0 | E29: =$W$25*EXP(($W$26-$W$28-0.5*$W$27^2)*C29+$W$27*SQRT(C29)*D29) -> 0 | F29: =$W$30*(1+$W$31)^C29 -> 0 | G29: =$W$32*(1+$W$33)^C29 -> 0 | H29: =$W$34*(1+$W$35)^C29 -> 0 | I29: =MIN(E29,F29) -> 0 | J29: =MIN(E29-I29,G29) -> 0 | K29: =MIN(E29-I29-J29,H29) -> 0 | L29: =E29-I29-J29-K29 -> 0 | M29: =IF((I29+J29+(1-$W$36)*L29)/$W$39>=$W$38,1,0) -> 0 | N29: =IF(M29=1,$W$37,$W$36)*L29 -> 0 | O29: =EXP(-$W$26*C29)*I29 -> 0 | P29: =EXP(-$W$26*C29)*J29 -> 0 | Q29: =EXP(-$W$26*C29)*K29 -> 0 | R29: =EXP(-$W$26*C29)*(L29-N29) -> 0 | S29: =EXP(-$W$26*C29)*N29 -> 0 | T29: =EXP(-$W$26*C29)*E29 -> 0 | V29: DLOM | W29: ='2. Inputs'!$C$12 -> 0
A30: 21 | B30: =RAND() -> 0 | C30: =IF(B30<$W$41,3,IF(B30<$W$41+$W$42,4,5)) -> 0 | D30: =NORMSINV(RAND()) -> 0 | E30: =$W$25*EXP(($W$26-$W$28-0.5*$W$27^2)*C30+$W$27*SQRT(C30)*D30) -> 0 | F30: =$W$30*(1+$W$31)^C30 -> 0 | G30: =$W$32*(1+$W$33)^C30 -> 0 | H30: =$W$34*(1+$W$35)^C30 -> 0 | I30: =MIN(E30,F30) -> 0 | J30: =MIN(E30-I30,G30) -> 0 | K30: =MIN(E30-I30-J30,H30) -> 0 | L30: =E30-I30-J30-K30 -> 0 | M30: =IF((I30+J30+(1-$W$36)*L30)/$W$39>=$W$38,1,0) -> 0 | N30: =IF(M30=1,$W$37,$W$36)*L30 -> 0 | O30: =EXP(-$W$26*C30)*I30 -> 0 | P30: =EXP(-$W$26*C30)*J30 -> 0 | Q30: =EXP(-$W$26*C30)*K30 -> 0 | R30: =EXP(-$W$26*C30)*(L30-N30) -> 0 | S30: =EXP(-$W$26*C30)*N30 -> 0 | T30: =EXP(-$W$26*C30)*E30 -> 0 | V30: 1. Loans — amount | W30: ='2. Inputs'!$C$14 -> 0
A31: 22 | B31: =RAND() -> 0 | C31: =IF(B31<$W$41,3,IF(B31<$W$41+$W$42,4,5)) -> 0 | D31: =NORMSINV(RAND()) -> 0 | E31: =$W$25*EXP(($W$26-$W$28-0.5*$W$27^2)*C31+$W$27*SQRT(C31)*D31) -> 0 | F31: =$W$30*(1+$W$31)^C31 -> 0 | G31: =$W$32*(1+$W$33)^C31 -> 0 | H31: =$W$34*(1+$W$35)^C31 -> 0 | I31: =MIN(E31,F31) -> 0 | J31: =MIN(E31-I31,G31) -> 0 | K31: =MIN(E31-I31-J31,H31) -> 0 | L31: =E31-I31-J31-K31 -> 0 | M31: =IF((I31+J31+(1-$W$36)*L31)/$W$39>=$W$38,1,0) -> 0 | N31: =IF(M31=1,$W$37,$W$36)*L31 -> 0 | O31: =EXP(-$W$26*C31)*I31 -> 0 | P31: =EXP(-$W$26*C31)*J31 -> 0 | Q31: =EXP(-$W$26*C31)*K31 -> 0 | R31: =EXP(-$W$26*C31)*(L31-N31) -> 0 | S31: =EXP(-$W$26*C31)*N31 -> 0 | T31: =EXP(-$W$26*C31)*E31 -> 0 | V31: 1. Loans — rate | W31: ='2. Inputs'!$C$15 -> 0
A32: 23 | B32: =RAND() -> 0 | C32: =IF(B32<$W$41,3,IF(B32<$W$41+$W$42,4,5)) -> 0 | D32: =NORMSINV(RAND()) -> 0 | E32: =$W$25*EXP(($W$26-$W$28-0.5*$W$27^2)*C32+$W$27*SQRT(C32)*D32) -> 0 | F32: =$W$30*(1+$W$31)^C32 -> 0 | G32: =$W$32*(1+$W$33)^C32 -> 0 | H32: =$W$34*(1+$W$35)^C32 -> 0 | I32: =MIN(E32,F32) -> 0 | J32: =MIN(E32-I32,G32) -> 0 | K32: =MIN(E32-I32-J32,H32) -> 0 | L32: =E32-I32-J32-K32 -> 0 | M32: =IF((I32+J32+(1-$W$36)*L32)/$W$39>=$W$38,1,0) -> 0 | N32: =IF(M32=1,$W$37,$W$36)*L32 -> 0 | O32: =EXP(-$W$26*C32)*I32 -> 0 | P32: =EXP(-$W$26*C32)*J32 -> 0 | Q32: =EXP(-$W$26*C32)*K32 -> 0 | R32: =EXP(-$W$26*C32)*(L32-N32) -> 0 | S32: =EXP(-$W$26*C32)*N32 -> 0 | T32: =EXP(-$W$26*C32)*E32 -> 0 | V32: 2. Prefs — amount | W32: ='2. Inputs'!$C$16 -> 0
A33: 24 | B33: =RAND() -> 0 | C33: =IF(B33<$W$41,3,IF(B33<$W$41+$W$42,4,5)) -> 0 | D33: =NORMSINV(RAND()) -> 0 | E33: =$W$25*EXP(($W$26-$W$28-0.5*$W$27^2)*C33+$W$27*SQRT(C33)*D33) -> 0 | F33: =$W$30*(1+$W$31)^C33 -> 0 | G33: =$W$32*(1+$W$33)^C33 -> 0 | H33: =$W$34*(1+$W$35)^C33 -> 0 | I33: =MIN(E33,F33) -> 0 | J33: =MIN(E33-I33,G33) -> 0 | K33: =MIN(E33-I33-J33,H33) -> 0 | L33: =E33-I33-J33-K33 -> 0 | M33: =IF((I33+J33+(1-$W$36)*L33)/$W$39>=$W$38,1,0) -> 0 | N33: =IF(M33=1,$W$37,$W$36)*L33 -> 0 | O33: =EXP(-$W$26*C33)*I33 -> 0 | P33: =EXP(-$W$26*C33)*J33 -> 0 | Q33: =EXP(-$W$26*C33)*K33 -> 0 | R33: =EXP(-$W$26*C33)*(L33-N33) -> 0 | S33: =EXP(-$W$26*C33)*N33 -> 0 | T33: =EXP(-$W$26*C33)*E33 -> 0 | V33: 2. Prefs — rate | W33: ='2. Inputs'!$C$17 -> 0
A34: 25 | B34: =RAND() -> 0 | C34: =IF(B34<$W$41,3,IF(B34<$W$41+$W$42,4,5)) -> 0 | D34: =NORMSINV(RAND()) -> 0 | E34: =$W$25*EXP(($W$26-$W$28-0.5*$W$27^2)*C34+$W$27*SQRT(C34)*D34) -> 0 | F34: =$W$30*(1+$W$31)^C34 -> 0 | G34: =$W$32*(1+$W$33)^C34 -> 0 | H34: =$W$34*(1+$W$35)^C34 -> 0 | I34: =MIN(E34,F34) -> 0 | J34: =MIN(E34-I34,G34) -> 0 | K34: =MIN(E34-I34-J34,H34) -> 0 | L34: =E34-I34-J34-K34 -> 0 | M34: =IF((I34+J34+(1-$W$36)*L34)/$W$39>=$W$38,1,0) -> 0 | N34: =IF(M34=1,$W$37,$W$36)*L34 -> 0 | O34: =EXP(-$W$26*C34)*I34 -> 0 | P34: =EXP(-$W$26*C34)*J34 -> 0 | Q34: =EXP(-$W$26*C34)*K34 -> 0 | R34: =EXP(-$W$26*C34)*(L34-N34) -> 0 | S34: =EXP(-$W$26*C34)*N34 -> 0 | T34: =EXP(-$W$26*C34)*E34 -> 0 | V34: 3. Rollover — amount | W34: ='2. Inputs'!$C$18 -> 0
A35: 26 | B35: =RAND() -> 0 | C35: =IF(B35<$W$41,3,IF(B35<$W$41+$W$42,4,5)) -> 0 | D35: =NORMSINV(RAND()) -> 0 | E35: =$W$25*EXP(($W$26-$W$28-0.5*$W$27^2)*C35+$W$27*SQRT(C35)*D35) -> 0 | F35: =$W$30*(1+$W$31)^C35 -> 0 | G35: =$W$32*(1+$W$33)^C35 -> 0 | H35: =$W$34*(1+$W$35)^C35 -> 0 | I35: =MIN(E35,F35) -> 0 | J35: =MIN(E35-I35,G35) -> 0 | K35: =MIN(E35-I35-J35,H35) -> 0 | L35: =E35-I35-J35-K35 -> 0 | M35: =IF((I35+J35+(1-$W$36)*L35)/$W$39>=$W$38,1,0) -> 0 | N35: =IF(M35=1,$W$37,$W$36)*L35 -> 0 | O35: =EXP(-$W$26*C35)*I35 -> 0 | P35: =EXP(-$W$26*C35)*J35 -> 0 | Q35: =EXP(-$W$26*C35)*K35 -> 0 | R35: =EXP(-$W$26*C35)*(L35-N35) -> 0 | S35: =EXP(-$W$26*C35)*N35 -> 0 | T35: =EXP(-$W$26*C35)*E35 -> 0 | V35: 3. Rollover — rate | W35: ='2. Inputs'!$C$19 -> 0
A36: 27 | B36: =RAND() -> 0 | C36: =IF(B36<$W$41,3,IF(B36<$W$41+$W$42,4,5)) -> 0 | D36: =NORMSINV(RAND()) -> 0 | E36: =$W$25*EXP(($W$26-$W$28-0.5*$W$27^2)*C36+$W$27*SQRT(C36)*D36) -> 0 | F36: =$W$30*(1+$W$31)^C36 -> 0 | G36: =$W$32*(1+$W$33)^C36 -> 0 | H36: =$W$34*(1+$W$35)^C36 -> 0 | I36: =MIN(E36,F36) -> 0 | J36: =MIN(E36-I36,G36) -> 0 | K36: =MIN(E36-I36-J36,H36) -> 0 | L36: =E36-I36-J36-K36 -> 0 | M36: =IF((I36+J36+(1-$W$36)*L36)/$W$39>=$W$38,1,0) -> 0 | N36: =IF(M36=1,$W$37,$W$36)*L36 -> 0 | O36: =EXP(-$W$26*C36)*I36 -> 0 | P36: =EXP(-$W$26*C36)*J36 -> 0 | Q36: =EXP(-$W$26*C36)*K36 -> 0 | R36: =EXP(-$W$26*C36)*(L36-N36) -> 0 | S36: =EXP(-$W$26*C36)*N36 -> 0 | T36: =EXP(-$W$26*C36)*E36 -> 0 | V36: Mgmt share — base | W36: ='2. Inputs'!$C$21 -> 0
A37: 28 | B37: =RAND() -> 0 | C37: =IF(B37<$W$41,3,IF(B37<$W$41+$W$42,4,5)) -> 0 | D37: =NORMSINV(RAND()) -> 0 | E37: =$W$25*EXP(($W$26-$W$28-0.5*$W$27^2)*C37+$W$27*SQRT(C37)*D37) -> 0 | F37: =$W$30*(1+$W$31)^C37 -> 0 | G37: =$W$32*(1+$W$33)^C37 -> 0 | H37: =$W$34*(1+$W$35)^C37 -> 0 | I37: =MIN(E37,F37) -> 0 | J37: =MIN(E37-I37,G37) -> 0 | K37: =MIN(E37-I37-J37,H37) -> 0 | L37: =E37-I37-J37-K37 -> 0 | M37: =IF((I37+J37+(1-$W$36)*L37)/$W$39>=$W$38,1,0) -> 0 | N37: =IF(M37=1,$W$37,$W$36)*L37 -> 0 | O37: =EXP(-$W$26*C37)*I37 -> 0 | P37: =EXP(-$W$26*C37)*J37 -> 0 | Q37: =EXP(-$W$26*C37)*K37 -> 0 | R37: =EXP(-$W$26*C37)*(L37-N37) -> 0 | S37: =EXP(-$W$26*C37)*N37 -> 0 | T37: =EXP(-$W$26*C37)*E37 -> 0 | V37: Mgmt share — ratcheted | W37: ='2. Inputs'!$C$22 -> 0
A38: 29 | B38: =RAND() -> 0 | C38: =IF(B38<$W$41,3,IF(B38<$W$41+$W$42,4,5)) -> 0 | D38: =NORMSINV(RAND()) -> 0 | E38: =$W$25*EXP(($W$26-$W$28-0.5*$W$27^2)*C38+$W$27*SQRT(C38)*D38) -> 0 | F38: =$W$30*(1+$W$31)^C38 -> 0 | G38: =$W$32*(1+$W$33)^C38 -> 0 | H38: =$W$34*(1+$W$35)^C38 -> 0 | I38: =MIN(E38,F38) -> 0 | J38: =MIN(E38-I38,G38) -> 0 | K38: =MIN(E38-I38-J38,H38) -> 0 | L38: =E38-I38-J38-K38 -> 0 | M38: =IF((I38+J38+(1-$W$36)*L38)/$W$39>=$W$38,1,0) -> 0 | N38: =IF(M38=1,$W$37,$W$36)*L38 -> 0 | O38: =EXP(-$W$26*C38)*I38 -> 0 | P38: =EXP(-$W$26*C38)*J38 -> 0 | Q38: =EXP(-$W$26*C38)*K38 -> 0 | R38: =EXP(-$W$26*C38)*(L38-N38) -> 0 | S38: =EXP(-$W$26*C38)*N38 -> 0 | T38: =EXP(-$W$26*C38)*E38 -> 0 | V38: Ratchet trigger (MoM ≥) | W38: ='2. Inputs'!$C$23 -> 0
A39: 30 | B39: =RAND() -> 0 | C39: =IF(B39<$W$41,3,IF(B39<$W$41+$W$42,4,5)) -> 0 | D39: =NORMSINV(RAND()) -> 0 | E39: =$W$25*EXP(($W$26-$W$28-0.5*$W$27^2)*C39+$W$27*SQRT(C39)*D39) -> 0 | F39: =$W$30*(1+$W$31)^C39 -> 0 | G39: =$W$32*(1+$W$33)^C39 -> 0 | H39: =$W$34*(1+$W$35)^C39 -> 0 | I39: =MIN(E39,F39) -> 0 | J39: =MIN(E39-I39,G39) -> 0 | K39: =MIN(E39-I39-J39,H39) -> 0 | L39: =E39-I39-J39-K39 -> 0 | M39: =IF((I39+J39+(1-$W$36)*L39)/$W$39>=$W$38,1,0) -> 0 | N39: =IF(M39=1,$W$37,$W$36)*L39 -> 0 | O39: =EXP(-$W$26*C39)*I39 -> 0 | P39: =EXP(-$W$26*C39)*J39 -> 0 | Q39: =EXP(-$W$26*C39)*K39 -> 0 | R39: =EXP(-$W$26*C39)*(L39-N39) -> 0 | S39: =EXP(-$W$26*C39)*N39 -> 0 | T39: =EXP(-$W$26*C39)*E39 -> 0 | V39: Sponsor money in | W39: ='2. Inputs'!$C$24 -> 0
A40: 31 | B40: =RAND() -> 0 | C40: =IF(B40<$W$41,3,IF(B40<$W$41+$W$42,4,5)) -> 0 | D40: =NORMSINV(RAND()) -> 0 | E40: =$W$25*EXP(($W$26-$W$28-0.5*$W$27^2)*C40+$W$27*SQRT(C40)*D40) -> 0 | F40: =$W$30*(1+$W$31)^C40 -> 0 | G40: =$W$32*(1+$W$33)^C40 -> 0 | H40: =$W$34*(1+$W$35)^C40 -> 0 | I40: =MIN(E40,F40) -> 0 | J40: =MIN(E40-I40,G40) -> 0 | K40: =MIN(E40-I40-J40,H40) -> 0 | L40: =E40-I40-J40-K40 -> 0 | M40: =IF((I40+J40+(1-$W$36)*L40)/$W$39>=$W$38,1,0) -> 0 | N40: =IF(M40=1,$W$37,$W$36)*L40 -> 0 | O40: =EXP(-$W$26*C40)*I40 -> 0 | P40: =EXP(-$W$26*C40)*J40 -> 0 | Q40: =EXP(-$W$26*C40)*K40 -> 0 | R40: =EXP(-$W$26*C40)*(L40-N40) -> 0 | S40: =EXP(-$W$26*C40)*N40 -> 0 | T40: =EXP(-$W$26*C40)*E40 -> 0 | V40: Mgmt price paid | W40: ='2. Inputs'!$C$25 -> 0
...

Sheet 6. Sensitivity
B2: Sensitivity — the two judgment inputs, side by side | I2: INPUTS USED ON THIS SHEET (linked from sheet 2 — change them THERE)
B3: Sweet equity value (Black-Scholes, BEFORE the DLOM) for combinations of volatility and exit year. | I3: V0 — the pot today | J3: ='2. Inputs'!$C$7 -> 0
B4: Any serious report shows this grid: it tells the reader how much the answer depends on judgment calls. | I4: r — risk-free rate | J4: ='2. Inputs'!$C$9 -> 0
I5: q — cash leakage | J5: ='2. Inputs'!$C$11 -> 0
B6: Hurdle at that exit year → | C6: =$J$7*(1+$J$8)^C7+$J$9*(1+$J$10)^C7+$J$11*(1+$J$12)^C7 -> 0 | D6: =$J$7*(1+$J$8)^D7+$J$9*(1+$J$10)^D7+$J$11*(1+$J$12)^D7 -> 0 | E6: =$J$7*(1+$J$8)^E7+$J$9*(1+$J$10)^E7+$J$11*(1+$J$12)^E7 -> 0 | F6: =$J$7*(1+$J$8)^F7+$J$9*(1+$J$10)^F7+$J$11*(1+$J$12)^F7 -> 0 | I6: Management share of ordinaries | J6: ='2. Inputs'!$C$21 -> 0
B7: volatility ↓ \ exit year → | C7: 3 | D7: 4 | E7: 5 | F7: 6 | G7: HOW TO READ IT | I7: 1. Loans — amount | J7: ='2. Inputs'!$C$14 -> 0
B8: 0.3 | C8: =$J$6*($J$3*EXP(-$J$5*C$7)*NORMSDIST((LN($J$3/C$6)+($J$4-$J$5+0.5*$B8^2)*C$7)/($B8*SQRT(C$7)))-C$6*EXP(-$J$4*C$7)*NORMSDIST((LN($J$3/C$6)+($J$4-$J$5+0.5*$B8^2)*C$7)/($B8*SQRT(C$7))-$B8*SQRT(C$7))) -> 0 | D8: =$J$6*($J$3*EXP(-$J$5*D$7)*NORMSDIST((LN($J$3/D$6)+($J$4-$J$5+0.5*$B8^2)*D$7)/($B8*SQRT(D$7)))-D$6*EXP(-$J$4*D$7)*NORMSDIST((LN($J$3/D$6)+($J$4-$J$5+0.5*$B8^2)*D$7)/($B8*SQRT(D$7))-$B8*SQRT(D$7))) -> 0 | E8: =$J$6*($J$3*EXP(-$J$5*E$7)*NORMSDIST((LN($J$3/E$6)+($J$4-$J$5+0.5*$B8^2)*E$7)/($B8*SQRT(E$7)))-E$6*EXP(-$J$4*E$7)*NORMSDIST((LN($J$3/E$6)+($J$4-$J$5+0.5*$B8^2)*E$7)/($B8*SQRT(E$7))-$B8*SQRT(E$7))) -> 0 | F8: =$J$6*($J$3*EXP(-$J$5*F$7)*NORMSDIST((LN($J$3/F$6)+($J$4-$J$5+0.5*$B8^2)*F$7)/($B8*SQRT(F$7)))-F$6*EXP(-$J$4*F$7)*NORMSDIST((LN($J$3/F$6)+($J$4-$J$5+0.5*$B8^2)*F$7)/($B8*SQRT(F$7))-$B8*SQRT(F$7))) -> 0 | G8: Down a column: more volatility always helps the sweet equity (options love uncertainty). | I8: 1. Loans — rate | J8: ='2. Inputs'!$C$15 -> 0
B9: 0.35 | C9: =$J$6*($J$3*EXP(-$J$5*C$7)*NORMSDIST((LN($J$3/C$6)+($J$4-$J$5+0.5*$B9^2)*C$7)/($B9*SQRT(C$7)))-C$6*EXP(-$J$4*C$7)*NORMSDIST((LN($J$3/C$6)+($J$4-$J$5+0.5*$B9^2)*C$7)/($B9*SQRT(C$7))-$B9*SQRT(C$7))) -> 0 | D9: =$J$6*($J$3*EXP(-$J$5*D$7)*NORMSDIST((LN($J$3/D$6)+($J$4-$J$5+0.5*$B9^2)*D$7)/($B9*SQRT(D$7)))-D$6*EXP(-$J$4*D$7)*NORMSDIST((LN($J$3/D$6)+($J$4-$J$5+0.5*$B9^2)*D$7)/($B9*SQRT(D$7))-$B9*SQRT(D$7))) -> 0 | E9: =$J$6*($J$3*EXP(-$J$5*E$7)*NORMSDIST((LN($J$3/E$6)+($J$4-$J$5+0.5*$B9^2)*E$7)/($B9*SQRT(E$7)))-E$6*EXP(-$J$4*E$7)*NORMSDIST((LN($J$3/E$6)+($J$4-$J$5+0.5*$B9^2)*E$7)/($B9*SQRT(E$7))-$B9*SQRT(E$7))) -> 0 | F9: =$J$6*($J$3*EXP(-$J$5*F$7)*NORMSDIST((LN($J$3/F$6)+($J$4-$J$5+0.5*$B9^2)*F$7)/($B9*SQRT(F$7)))-F$6*EXP(-$J$4*F$7)*NORMSDIST((LN($J$3/F$6)+($J$4-$J$5+0.5*$B9^2)*F$7)/($B9*SQRT(F$7))-$B9*SQRT(F$7))) -> 0 | G9: Across a row: more years is NOT automatically better — the growing time value fights the | I9: 2. Prefs — amount | J9: ='2. Inputs'!$C$16 -> 0
B10: 0.4 | C10: =$J$6*($J$3*EXP(-$J$5*C$7)*NORMSDIST((LN($J$3/C$6)+($J$4-$J$5+0.5*$B10^2)*C$7)/($B10*SQRT(C$7)))-C$6*EXP(-$J$4*C$7)*NORMSDIST((LN($J$3/C$6)+($J$4-$J$5+0.5*$B10^2)*C$7)/($B10*SQRT(C$7))-$B10*SQRT(C$7))) -> 0 | D10: =$J$6*($J$3*EXP(-$J$5*D$7)*NORMSDIST((LN($J$3/D$6)+($J$4-$J$5+0.5*$B10^2)*D$7)/($B10*SQRT(D$7)))-D$6*EXP(-$J$4*D$7)*NORMSDIST((LN($J$3/D$6)+($J$4-$J$5+0.5*$B10^2)*D$7)/($B10*SQRT(D$7))-$B10*SQRT(D$7))) -> 0 | E10: =$J$6*($J$3*EXP(-$J$5*E$7)*NORMSDIST((LN($J$3/E$6)+($J$4-$J$5+0.5*$B10^2)*E$7)/($B10*SQRT(E$7)))-E$6*EXP(-$J$4*E$7)*NORMSDIST((LN($J$3/E$6)+($J$4-$J$5+0.5*$B10^2)*E$7)/($B10*SQRT(E$7))-$B10*SQRT(E$7))) -> 0 | F10: =$J$6*($J$3*EXP(-$J$5*F$7)*NORMSDIST((LN($J$3/F$6)+($J$4-$J$5+0.5*$B10^2)*F$7)/($B10*SQRT(F$7)))-F$6*EXP(-$J$4*F$7)*NORMSDIST((LN($J$3/F$6)+($J$4-$J$5+0.5*$B10^2)*F$7)/($B10*SQRT(F$7))-$B10*SQRT(F$7))) -> 0 | G10: growing hurdle (grey row above). Whichever wins here, check it rather than assume it. | I10: 2. Prefs — rate | J10: ='2. Inputs'!$C$17 -> 0
B11: 0.45 | C11: =$J$6*($J$3*EXP(-$J$5*C$7)*NORMSDIST((LN($J$3/C$6)+($J$4-$J$5+0.5*$B11^2)*C$7)/($B11*SQRT(C$7)))-C$6*EXP(-$J$4*C$7)*NORMSDIST((LN($J$3/C$6)+($J$4-$J$5+0.5*$B11^2)*C$7)/($B11*SQRT(C$7))-$B11*SQRT(C$7))) -> 0 | D11: =$J$6*($J$3*EXP(-$J$5*D$7)*NORMSDIST((LN($J$3/D$6)+($J$4-$J$5+0.5*$B11^2)*D$7)/($B11*SQRT(D$7)))-D$6*EXP(-$J$4*D$7)*NORMSDIST((LN($J$3/D$6)+($J$4-$J$5+0.5*$B11^2)*D$7)/($B11*SQRT(D$7))-$B11*SQRT(D$7))) -> 0 | E11: =$J$6*($J$3*EXP(-$J$5*E$7)*NORMSDIST((LN($J$3/E$6)+($J$4-$J$5+0.5*$B11^2)*E$7)/($B11*SQRT(E$7)))-E$6*EXP(-$J$4*E$7)*NORMSDIST((LN($J$3/E$6)+($J$4-$J$5+0.5*$B11^2)*E$7)/($B11*SQRT(E$7))-$B11*SQRT(E$7))) -> 0 | F11: =$J$6*($J$3*EXP(-$J$5*F$7)*NORMSDIST((LN($J$3/F$6)+($J$4-$J$5+0.5*$B11^2)*F$7)/($B11*SQRT(F$7)))-F$6*EXP(-$J$4*F$7)*NORMSDIST((LN($J$3/F$6)+($J$4-$J$5+0.5*$B11^2)*F$7)/($B11*SQRT(F$7))-$B11*SQRT(F$7))) -> 0 | I11: 3. Rollover — amount | J11: ='2. Inputs'!$C$18 -> 0
B12: 0.5 | C12: =$J$6*($J$3*EXP(-$J$5*C$7)*NORMSDIST((LN($J$3/C$6)+($J$4-$J$5+0.5*$B12^2)*C$7)/($B12*SQRT(C$7)))-C$6*EXP(-$J$4*C$7)*NORMSDIST((LN($J$3/C$6)+($J$4-$J$5+0.5*$B12^2)*C$7)/($B12*SQRT(C$7))-$B12*SQRT(C$7))) -> 0 | D12: =$J$6*($J$3*EXP(-$J$5*D$7)*NORMSDIST((LN($J$3/D$6)+($J$4-$J$5+0.5*$B12^2)*D$7)/($B12*SQRT(D$7)))-D$6*EXP(-$J$4*D$7)*NORMSDIST((LN($J$3/D$6)+($J$4-$J$5+0.5*$B12^2)*D$7)/($B12*SQRT(D$7))-$B12*SQRT(D$7))) -> 0 | E12: =$J$6*($J$3*EXP(-$J$5*E$7)*NORMSDIST((LN($J$3/E$6)+($J$4-$J$5+0.5*$B12^2)*E$7)/($B12*SQRT(E$7)))-E$6*EXP(-$J$4*E$7)*NORMSDIST((LN($J$3/E$6)+($J$4-$J$5+0.5*$B12^2)*E$7)/($B12*SQRT(E$7))-$B12*SQRT(E$7))) -> 0 | F12: =$J$6*($J$3*EXP(-$J$5*F$7)*NORMSDIST((LN($J$3/F$6)+($J$4-$J$5+0.5*$B12^2)*F$7)/($B12*SQRT(F$7)))-F$6*EXP(-$J$4*F$7)*NORMSDIST((LN($J$3/F$6)+($J$4-$J$5+0.5*$B12^2)*F$7)/($B12*SQRT(F$7))-$B12*SQRT(F$7))) -> 0 | G12: If the value swings a lot inside the plausible input range, say so in the report — that IS a finding. | I12: 3. Rollover — rate | J12: ='2. Inputs'!$C$19 -> 0
B13: 0.55 | C13: =$J$6*($J$3*EXP(-$J$5*C$7)*NORMSDIST((LN($J$3/C$6)+($J$4-$J$5+0.5*$B13^2)*C$7)/($B13*SQRT(C$7)))-C$6*EXP(-$J$4*C$7)*NORMSDIST((LN($J$3/C$6)+($J$4-$J$5+0.5*$B13^2)*C$7)/($B13*SQRT(C$7))-$B13*SQRT(C$7))) -> 0 | D13: =$J$6*($J$3*EXP(-$J$5*D$7)*NORMSDIST((LN($J$3/D$6)+($J$4-$J$5+0.5*$B13^2)*D$7)/($B13*SQRT(D$7)))-D$6*EXP(-$J$4*D$7)*NORMSDIST((LN($J$3/D$6)+($J$4-$J$5+0.5*$B13^2)*D$7)/($B13*SQRT(D$7))-$B13*SQRT(D$7))) -> 0 | E13: =$J$6*($J$3*EXP(-$J$5*E$7)*NORMSDIST((LN($J$3/E$6)+($J$4-$J$5+0.5*$B13^2)*E$7)/($B13*SQRT(E$7)))-E$6*EXP(-$J$4*E$7)*NORMSDIST((LN($J$3/E$6)+($J$4-$J$5+0.5*$B13^2)*E$7)/($B13*SQRT(E$7))-$B13*SQRT(E$7))) -> 0 | F13: =$J$6*($J$3*EXP(-$J$5*F$7)*NORMSDIST((LN($J$3/F$6)+($J$4-$J$5+0.5*$B13^2)*F$7)/($B13*SQRT(F$7)))-F$6*EXP(-$J$4*F$7)*NORMSDIST((LN($J$3/F$6)+($J$4-$J$5+0.5*$B13^2)*F$7)/($B13*SQRT(F$7))-$B13*SQRT(F$7))) -> 0
B14: 0.6 | C14: =$J$6*($J$3*EXP(-$J$5*C$7)*NORMSDIST((LN($J$3/C$6)+($J$4-$J$5+0.5*$B14^2)*C$7)/($B14*SQRT(C$7)))-C$6*EXP(-$J$4*C$7)*NORMSDIST((LN($J$3/C$6)+($J$4-$J$5+0.5*$B14^2)*C$7)/($B14*SQRT(C$7))-$B14*SQRT(C$7))) -> 0 | D14: =$J$6*($J$3*EXP(-$J$5*D$7)*NORMSDIST((LN($J$3/D$6)+($J$4-$J$5+0.5*$B14^2)*D$7)/($B14*SQRT(D$7)))-D$6*EXP(-$J$4*D$7)*NORMSDIST((LN($J$3/D$6)+($J$4-$J$5+0.5*$B14^2)*D$7)/($B14*SQRT(D$7))-$B14*SQRT(D$7))) -> 0 | E14: =$J$6*($J$3*EXP(-$J$5*E$7)*NORMSDIST((LN($J$3/E$6)+($J$4-$J$5+0.5*$B14^2)*E$7)/($B14*SQRT(E$7)))-E$6*EXP(-$J$4*E$7)*NORMSDIST((LN($J$3/E$6)+($J$4-$J$5+0.5*$B14^2)*E$7)/($B14*SQRT(E$7))-$B14*SQRT(E$7))) -> 0 | F14: =$J$6*($J$3*EXP(-$J$5*F$7)*NORMSDIST((LN($J$3/F$6)+($J$4-$J$5+0.5*$B14^2)*F$7)/($B14*SQRT(F$7)))-F$6*EXP(-$J$4*F$7)*NORMSDIST((LN($J$3/F$6)+($J$4-$J$5+0.5*$B14^2)*F$7)/($B14*SQRT(F$7))-$B14*SQRT(F$7))) -> 0

Sheet 7. Parameter guide
B2: Quick reference — every parameter (full plain-words detail: Word guide §5)
B4: Parameter | C4: What it is | D4: Where it comes from | E4: Effect on the sweet equity value
B5: V0 — the pot | C5: Today's value of all 5 classes together (company value minus bank debt). | D5: The deal itself at/near completion (everyone together paid €240m); later: multiples/DCF. | E5: Biggest driver; effect is leveraged (+10% pot can be +30% sweet equity).
B6: Queue amounts & PIK rates | C6: What each senior class is owed, growing every year at its rolled-up rate. | D6: Funds flow statement (amounts); loan notes & articles (rates, compounding). | E6: Bigger/faster-growing queue = higher hurdle = lower value; rate damage compounds with T.
B7: T — years to exit | C7: When the sale happens and the queue is settled. | D7: Sponsor plan, fund life. Typically 3–5y. | E7: Two-sided: growth time vs queue roll-up. Check sheet 6, don't assume.
B8: sigma — volatility | C8: Yearly swing of the pot's value. | D8: Listed comparables, adjusted (de/re-levered) for this deal's debt. 35–60% typical. | E8: More swing = more value (downside capped at zero). Most judgmental input.
B9: r — risk-free rate | C9: Government bond yield, same horizon & currency. | D9: Market data at valuation date. | E9: Small positive effect. NOTE: the only rate in the model — a WACC anywhere is a red flag.
B10: q — leakage | C10: Cash paid out of the pot before exit. | D10: Instrument terms: PIK (stays in, q=0) vs cash-pay. | E10: Leakage shrinks the exit pot; hurts the back of the queue most.
B11: DLOM | C11: Haircut because the shares can't be sold before exit. | D11: Chaffe/Finnerty put methods or studies; 10–30% typical. | E11: Reduces the conclusion one-for-one. Apply to the sweet equity only.
B12: Ratchet | C12: Management's % steps up (15%→20%) if sponsor money-multiple ≥ 2.5×. | D12: MIP term sheet / SHA — read the exact test. | E12: Adds value in good scenarios only; needs the Monte Carlo, not the formula.
B13: Exit-year probabilities | C13: Weights over year 3/4/5 instead of one fixed date. | D13: Sponsor evidence, fund life. | E13: Each year has a different hurdle (roll-up), so timing genuinely moves value.
B14: Leaver / vesting | C14: Forfeiture risk if a manager departs early. | D14: SHA leaver clauses; vesting schedule. | E14: Haircuts the value; keep it explicit and separate (not modelled in this example).
